{"uuid": "609fc624-7591-449b-b2a5-05c659d7260c", "children": ["5ce2f69a-2b87-4a01-9ee4-ab907f58b76b"], "befores": [{"name": "set_up", "status": "passed", "start": 1567676461704, "stop": 1567676466765}], "afters": [{"name": "set_up::0", "status": "broken", "statusDetails": {"message": "urllib3.exceptions.MaxRetryError: HTTPConnectionPool(host='127.0.0.1', port=16677): Max retries exceeded with url: /session/12ec504b64c42d2e1fb285a58c2c19cd/window (Caused by NewConnectionError('<urllib3.connection.HTTPConnection object at 0x00E3E990>: Failed to establish a new connection: [WinError 10061] No connection could be made because the target machine actively refused it',))\n", "trace": "  File \"c:\\users\\z003d7tu\\appdata\\local\\programs\\python\\python36-32\\lib\\site-packages\\allure_commons\\_allure.py\", line 185, in __call__\n    return self._fixture_function(*args, **kwargs)\n  File \"c:\\users\\z003d7tu\\appdata\\local\\programs\\python\\python36-32\\lib\\site-packages\\_pytest\\fixtures.py\", line 786, in _teardown_yield_fixture\n    next(it)\n  File \"D:\\_python\\themis\\Tests/..\\Base\\base.py\", line 21, in set_up\n    self.driver.close()\n  File \"c:\\users\\z003d7tu\\appdata\\local\\programs\\python\\python36-32\\lib\\site-packages\\selenium\\webdriver\\remote\\webdriver.py\", line 688, in close\n    self.execute(Command.CLOSE)\n  File \"c:\\users\\z003d7tu\\appdata\\local\\programs\\python\\python36-32\\lib\\site-packages\\selenium\\webdriver\\remote\\webdriver.py\", line 319, in execute\n    response = self.command_executor.execute(driver_command, params)\n  File \"c:\\users\\z003d7tu\\appdata\\local\\programs\\python\\python36-32\\lib\\site-packages\\selenium\\webdriver\\remote\\remote_connection.py\", line 374, in execute\n    return self._request(command_info[0], url, body=data)\n  File \"c:\\users\\z003d7tu\\appdata\\local\\programs\\python\\python36-32\\lib\\site-packages\\selenium\\webdriver\\remote\\remote_connection.py\", line 397, in _request\n    resp = self._conn.request(method, url, body=body, headers=headers)\n  File \"c:\\users\\z003d7tu\\appdata\\local\\programs\\python\\python36-32\\lib\\site-packages\\urllib3\\request.py\", line 68, in request\n    **urlopen_kw)\n  File \"c:\\users\\z003d7tu\\appdata\\local\\programs\\python\\python36-32\\lib\\site-packages\\urllib3\\request.py\", line 89, in request_encode_url\n    return self.urlopen(method, url, **extra_kw)\n  File \"c:\\users\\z003d7tu\\appdata\\local\\programs\\python\\python36-32\\lib\\site-packages\\urllib3\\poolmanager.py\", line 323, in urlopen\n    response = conn.urlopen(method, u.request_uri, **kw)\n  File \"c:\\users\\z003d7tu\\appdata\\local\\programs\\python\\python36-32\\lib\\site-packages\\urllib3\\connectionpool.py\", line 667, in urlopen\n    **response_kw)\n  File \"c:\\users\\z003d7tu\\appdata\\local\\programs\\python\\python36-32\\lib\\site-packages\\urllib3\\connectionpool.py\", line 667, in urlopen\n    **response_kw)\n  File \"c:\\users\\z003d7tu\\appdata\\local\\programs\\python\\python36-32\\lib\\site-packages\\urllib3\\connectionpool.py\", line 667, in urlopen\n    **response_kw)\n  File \"c:\\users\\z003d7tu\\appdata\\local\\programs\\python\\python36-32\\lib\\site-packages\\urllib3\\connectionpool.py\", line 638, in urlopen\n    _stacktrace=sys.exc_info()[2])\n  File \"c:\\users\\z003d7tu\\appdata\\local\\programs\\python\\python36-32\\lib\\site-packages\\urllib3\\util\\retry.py\", line 398, in increment\n    raise MaxRetryError(_pool, url, error or ResponseError(cause))\n"}, "start": 1567676725383, "stop": 1567676729408}], "start": 1567676461704, "stop": 1567676729408}